Workbook

Sheet DATOS GENERALES
F1: INFORME INSTALACIÓN UPS TRIFÁSICA
A9: ID SEDE: | K9: TIPO DE EQUIPO: | L9: UPS | R9: UBICACIÓN: | S9: =F18 -> 0
A10: FECHA: | K10: DIRECCIÓN:
A11: REGIONAL: | K11: CIUDAD:
A12: NOMBRE DE LA SEDE: | K12: DEPARTAMENTO:
A13: COORDINADOR: | K13: TELÉFONO:
A15: 1 - DATOS DE LA UPS INSTALADA
A16: MARCA: | D16: MODELO: | I16: CAPACIDAD: (KVA) | K16: NÚMERO DE FASES: | O16: SERIE: | R16: AIRE ACONDICIONADO: | T16: TEMPERATURA AMBIENTE: (°C)
A17: TARJETA SNMP | C17: MARCA | L17: NUMERO DE SERIE TARJETA SNMP
A18: 2 -ÁREA DE UBICACION DEL EQUIPO EN LA SEDE:
A20: ESPACIOS REQUERIDOS PARA LA UPS
A21: Distancia libre al lado izquierdo igual o mayor a 75 cm: | E21: SI | H21: NO | J21: Distancia libre al lado derecho igual o mayor a 75 cm: | O21: SI | R21: NO
A22: Distancia libre al frente igual o mayor a 90 cm: | E22: SI | H22: NO | J22: La puerta del tablero abre a 90°: | O22: SI | R22: NO
A23: OBSERVACIONES DE LAS DISTANCIAS Y ESPACIOS
A24: 3 - ESTADO DE CONEXIONES UPS (Check List)
A25: ITEM | C25: SI | F25: NO | I25: ITEM | M25: SI | O25: NO | Q25: ITEM | S25: SI | U25: NO
A26: El equipo esta en un cuarto tecnico | I26: Conexiones de entrada firmes | Q26: Conexiones de baterias firmes
A27: Accesibilidad al equipo buena | I27: Conexiones de salida firmes | Q27: conexión de tierra
A28: Estado de la carcasa bueno | I28: Equipo en gestión | Q28: Conexión del patch cord
A29: Alarmas activas | I29: Conductores en buen estado | Q29: Cantidad total de baterias
A30: Codigo Alarma activa
A31: 4 - INSPECCION DE LAS INSTALACIONES
A32: CONDUCTORES DE ENTRADA | E32: Número de fases: | L32: 2. CONDUCTORES DE SALIDA | O32: Número de fases:
A33: CALIBRE CONDUCTORES (AWG o KCMIL) | C33: Fases: | G33: Neutro: | J33: Tierra: | L33: CALIBRE CONDUCTORES (AWG o KCMIL) | Q33: Fases: | S33: Neutro: | U33: Tierra:
A34: COLOR DE MARQUILLADO DE LOS CONDUCTORES DE FASE: | C34: Ø A: | G34: Ø B: | J34: Ø C: | L34: COLOR DE MARQUILLADO DE LOS CONDUCTORES DE FASE: | Q34: Ø A: | S34: Ø B: | U34: Ø C:
A35: CANALIZACION Y DIMENSIONES | I35: LONGITUD | L35: CANALIZACION Y DIMENSIONES | R35: LONGITUD
A36: OBSERVACIONES CONDUCTORES DE EQUIPOS:
A38: 5 - INDIQUE CON UNA (X) QUE ALIMENTA LA UPS
A39: PDU | C39: TABLERO REGULADO | I39: MULTITOMA | M39: RACK DIRECTAMENTE | Q39: OTRO | T39: CUAL
A40: 6 - TABLERO DE ENTRADA A LA UPS
A41: BREAKER ENTRADA UPS | B41: SI | C41: NO | F41: MONOFÁSICO, BIFÁSICO, TRIFÁSICO | J41: MARCA: | M41: CAPACIDAD (A): | R41: CAPACIDAD DE CORTO CIRCUITO (KA):
A42: DPS ENTRADA | B42: SI | C42: NO | F42: MARCA | M42: REFERENCIA
A43: 7 - TABLERO DE SALIDA A LA UPS
A44: BREAKER SALIDA UPS | B44: SI | C44: NO | F44: MONOFÁSICO, BIFÁSICO, TRIFÁSICO | J44: MARCA: | M44: CAPACIDAD (A): | R44: CAPACIDAD DE CORTO CIRCUITO (KA):
A45: DPS SALIDA | B45: SI | C45: NO | F45: MARCA | M45: REFERENCIA
A47: 8 - PARAMETROS ELÉCTRICOS DE ENTRADA
A48: Tensión de Entrada F-F (VAC): | C48: Ø A - B: | E48: Ø B - C: | G48: Ø A - C: | I48: Corriente de Entrada (AAC) | K48: Ø A: | M48: Ø B: | O48: Ø C: | R48: Neutro: | T48: Tierra:
A49: Tensión de Entrada F-N (VAC): | C49: Ø A - N: | E49: Ø B - N: | G49: Ø C - N: | I49: Corriente de Salida (AAC) | K49: Ø A: | M49: Ø B: | O49: Ø C: | R49: Neutro: | T49: Tierra:
A50: Tensión entre Neutro y Tierra Entrada (V):
A51: 9 - PARAMETROS ELÉCTRICOS DE SALIDA
...

Sheet EVIDENCIA DE LA INSTALACIÓN
B1: REGISTRO FOTOGRÁFICO INSTALACIÓN DE LA UPS
A2: Panorámica Ubicación de la UPS | B2: Vista Frontal de la UPS | C2: Vista Posterior de la UPS | D2: Vista Superior de la UPS
A20: Vista Lateral Izquierda | B20: Vista Lateral Derecha | C20: Placa con Serial de la UPS | D20: Placa de Entidad (solo si aplica)
A38: Placa con Serial de laTarjeta SNMP | B38: Tablero de Red Eléctrica Regulada | C38: Breaker de Entrada de UPS | D38: DPS Entrada de UPS
A56: Breaker de Salida de UPS | B56: DPS Salida de UPS | C56: Sistema de Transferencia Manual de Bypass | D56: Barraje Equipotencial de Tierra
A74: Diagrama Eléctrico Unifilar | B74: Canalización de Entrada | C74: Canalización de Salida | D74: Foto Aire Acondicionado
A92: Diagrama Eléctrico Unifilar | B92: Canalización de Entrada | C92: Canalización de Salida | D92: Foto Aire Acondicionado
A110: OBSERVACIONES

Sheet MEDICIONES ENTRADA DE UPS
B1: REGISTRO FOTOGRÁFICO MEDICIONES DE ENTRADA A LA UPS
A2: TIPO DE ALIMENTACIÓN | C2: TRIFÁSICA
A3: Tensión AC Fase A - Neutro | C3: Tensión AC Fase B - Neutro | E3: Tensión AC Fase C - Neutro
A21: Tensión AC Fase A - Fase B | C21: Tensión AC Fase B - Fase C | E21: Tensión AC Fase A - Fase C
A39: Tensión Neutro Tierra | C39: Corriente por Fase A | E39: Corriente por Fase B
A57: Corriente por Fase C | C57: Corriente por Neutro | E57: Corriente por Tierra
A75: MEDIDAS ELÉCTRICAS
A76: TIPO DE ALIMENTACIÓN | C76: TRIFÁSICA
A77: MEDICIONES DE TENSIÓN | C77: MEDICIONES DE CORRIENTE | E77: CALIBRE DE ACOMETIDAS
A78: TENSIÓN FASE A - NEUTRO (VAC) | B78: ='DATOS GENERALES'!D49 -> 0 | C78: CORRIENTE POR FASE A (AAC) | D78: ='DATOS GENERALES'!L48 -> 0 | E78: CALIBRE FASE A | F78: =+'DATOS GENERALES'!E33 -> 0 | G78: 0
A79: TENSIÓN FASE B - NEUTRO (VAC) | B79: ='DATOS GENERALES'!F49 -> 0 | C79: CORRIENTE POR FASE B (AAC) | D79: ='DATOS GENERALES'!N48 -> 0 | E79: CALIBRE FASE B | F79: =+'DATOS GENERALES'!E33 -> 0 | G79: 0
A80: TENSIÓN FASE C - NEUTRO (VAC) | B80: ='DATOS GENERALES'!H49 -> 0 | C80: CORRIENTE POR FASE C (AAC) | D80: ='DATOS GENERALES'!Q49 -> 0 | E80: CALIBRE FASE C | F80: =+'DATOS GENERALES'!E33 -> 0 | G80: 0
A81: TENSIÓN FASE A - FASE B (VAC) | B81: ='DATOS GENERALES'!D48 -> 0 | C81: CORRIENTE POR NEUTRO (AAC) | D81: ='DATOS GENERALES'!S48 -> 0 | E81: CALIBRE NEUTRO | F81: =+'DATOS GENERALES'!I33 -> 0
A82: TENSIÓN FASE B - FASE C (VAC) | B82: ='DATOS GENERALES'!F48 -> 0 | C82: CORRIENTE TIERRA (AAC) | D82: ='DATOS GENERALES'!U48 -> 0 | E82: CALIBRE TIERRA | F82: =+'DATOS GENERALES'!K33 -> 0
A83: TENSIÓN FASE A - FASE C (VAC) | B83: ='DATOS GENERALES'!H48 -> 0 | C83: FRECUENCIA (Hz) | D83: 60
A84: TENSIÓN NEUTRO - TIERRA (VAC) | B84: {='DATOS GENERALES'!C50:H50} -> 0 | C84: 0 | D84: 0 | E84: 0 | F84: 0 | G84: 0
A85: OBSERVACIONES

Sheet MEDICIONES SALIDA DE UPS
B1: REGISTRO FOTOGRÁFICO MEDICIONES SALIDA Y AUTONOMÍA UPS
A2: TIPO DE ALIMENTACION | C2: TRIFÁSICA
A3: Tensión AC Fase A - Neutro | C3: Tensión AC Fase B - Neutro | E3: Tensión AC Fase C - Neutro
A21: Tensión AC Fase A - Fase B | C21: Tensión AC Fase B - Fase C | E21: Tensión AC Fase A - Fase C
A39: Tensión Neutro Tierra | C39: Corriente por Fase A | E39: Corriente por Fase B
A57: Corriente por Fase C | C57: Corriente por Neutro | E57: Corriente por Tierra
A75: MEDIDAS ELÉCTRICAS
A76: TIPO DE ALIMENTACION | C76: TRIFÁSICA
A77: MEDICIONES DE TENSIÓN | C77: MEDICIONES DE CORRIENTE | E77: CALIBRE DE ACOMETIDAS
A78: TENSIÓN FASE A - NEUTRO (VAC) | B78: ='DATOS GENERALES'!D53 -> 0 | C78: CORRIENTE POR FASE A (AAC) | D78: ='DATOS GENERALES'!L49 -> 0 | E78: CALIBRE FASE A | F78: ='DATOS GENERALES'!R33 -> 0
A79: TENSIÓN FASE B - NEUTRO (VAC) | B79: ='DATOS GENERALES'!F53 -> 0 | C79: CORRIENTE POR FASE B (AAC) | D79: ='DATOS GENERALES'!N49 -> 0 | E79: CALIBRE FASE B | F79: ='DATOS GENERALES'!R33 -> 0
A80: TENSIÓN FASE C - NEUTRO (VAC) | B80: ='DATOS GENERALES'!H53 -> 0 | C80: CORRIENTE POR FASE C (AAC) | D80: ='DATOS GENERALES'!Q49 -> 0 | E80: CALIBRE FASE C | F80: ='DATOS GENERALES'!R33 -> 0
A81: TENSIÓN FASE A - FASE B (VAC) | B81: ='DATOS GENERALES'!D52 -> 0 | C81: CORRIENTE POR NEUTRO (AAC) | D81: ='DATOS GENERALES'!S49 -> 0 | E81: CALIBRE NEUTRO | F81: ='DATOS GENERALES'!T33 -> 0
A82: TENSIÓN FASE B - FASE C (VAC) | B82: ='DATOS GENERALES'!F52 -> 0 | C82: CORRIENTE POR TIERRA (AAC) | D82: ='DATOS GENERALES'!U49 -> 0 | E82: CALIBRE TIERRA | F82: {='DATOS GENERALES'!V33:W33} -> 0 | G82: 0
A83: TENSIÓN FASE A - FASE C (VAC) | B83: ='DATOS GENERALES'!H53 -> 0 | C83: FRECUENCIA (Hz) | D83: 60
A84: TENSIÓN NEUTRO - TIERRA (VAC) | B84: ='DATOS GENERALES'!M52 -> 0
A85: OBSERVACIONES

Sheet DISPLAY DE LA UPS
B1: INFORMACIÓN Y DATOS DEL DISPLAY
A2: TIPO DE ALIMENTACIÓN: | C2: TRIFÁSICA
A3: Display Información UPS Acerca de: | C3: Display Condición Normal de Operación En Línea | E3: Display Condición Soporte en Modo Baterías | G3: Display Potencia de Salida Pantalla 1/5
A21: Display Datos de Salida Pantalla 2/5 | C21: Display Datos de Batería Pantalla 3/5 | E21: Display Datos de Bypass Pantalla 4/5 | G21: Display Datos de Bypass Pantalla 5/5
A39: OBSERVACIONES

Sheet BATERIAS
B1: REGISTRO FOTOGRÁFICO DEL BANCO DE BATERÍAS
A2: CARACTERISTICAS TÉCNICAS DE LAS BATERIAS INSTALADAS
A3: Marca de las Baterías: | C3: Referencia de las Baterías: | E3: Amperaje de las Baterías: | G3: Cantidad Total de Baterías:
A4: Foto Frontal con Características de las Baterias | C4: Tensión Normal de Baterías Inicial (VDC): | E4: Tensión de Baterías Soporte Durante 5 Minutos (VDC) | G4: Tensión de Baterías en Carga (VDC)
A24: CONCLUSIONES DE LA PRUEBA:

Sheet NOVEDADES
B1: REGISTRO FOTOGRÁFICO DE NOVEDADES ENCONTRADAS
A2: TIPO DE ALIMENTACIÓN: | C2: MONOFÁSICA
A3: Primer Novedad | C3: Segunda Novedad | E3: Tercer Novedad | G3: Cuarta Novedad
A21: Quita Novedad
A38: NOVEDADES | B38: TIPO | C38: Ambiental
C39: UPS
A40: OBSERVACIONES
